<?xml version="1.0" ?>
<!-- =================================================================================== -->
<!-- |    This document was autogenerated by xacro from src/Matlab_urdf/urdf/spot.urdf.xacro | -->
<!-- |    EDITING THIS FILE BY HAND IS NOT RECOMMENDED                                 | -->
<!-- =================================================================================== -->
<!-- the code was inspired by this git hub link https://github.com/SoftServeSAG/
spot_simulation/tree/spot_control-->
<!--make sure to check mesh filename if its in the correct location-->
<robot name="spot">
<!-- Body -->
  <link name="body">
    <visual>
      <geometry>
        <mesh filename="/home/youssefokab/catkin_ws/src/Matlab_urdf/meshes/body.stl"/>
      </geometry>
    </visual>
    <collision>
      <geometry>
        <mesh filename="/home/youssefokab/catkin_ws/src/Matlab_urdf/meshes/body_collision.stl"/>
      </geometry>
    </collision>
    <inertial>
      <mass value="16.25"/>
      <inertia ixx="0.085" ixy="0.0" ixz="0.0" iyy="1.045" iyz="0.0" izz="1.042"/>
    </inertial>
  </link>
<!-- rear_right_hip -->
  <link name="rear_right_hip">
    <visual>
      <geometry>
        <mesh filename="/home/youssefokab/catkin_ws/src/Matlab_urdf/meshes/rear_right_hip.stl"/>
      </geometry>
    </visual>
    <collision>
      <geometry>
        <mesh filename="/home/youssefokab/catkin_ws/src/Matlab_urdf/meshes/rear_right_hip_collision.stl"/>
      </geometry>
    </collision>
    <inertial>
      <mass value="1.5"/>
      <inertia ixx="0.0605" ixy="0.0" ixz="0.0" iyy="0.0" iyz="0.0" izz="0.0"/>
    </inertial>
  </link>
  <joint name="rear_right_hip_x" type="revolute">
    <origin rpy="0 0 0" xyz="-0.29785 -0.05500 0.00000"/>
    <axis xyz="1 0 0"/>
    <parent link="body"/>
    <child link="rear_right_hip"/>
    <dynamics damping="0.1" friction="0.1"/>
    <limit effort="1000" lower="-0.78539816339744827899" upper="0.78539816339744827899" velocity="1000.00"/>
  </joint>
  <transmission name="rear_right_hip_x_trans">
    <type>transmission_interface/SimpleTransmission</type>
    <joint name="rear_right_hip_x">
      <hardwareInterface>EffortJointInterface</hardwareInterface>
    </joint>
    <actuator name="rear_right_hip_x">
      <mechanicalReduction>50</mechanicalReduction>
      <hardwareInterface>EffortJointInterface</hardwareInterface>
    </actuator>
  </transmission>
  <!-- rear_right_upper_leg -->
  <link name="rear_right_upper_leg">
    <visual>
      <geometry>
        <mesh filename="/home/youssefokab/catkin_ws/src/Matlab_urdf/meshes/rear_right_upper_leg.stl"/>
      </geometry>
    </visual>
    <collision>
      <geometry>
        <mesh filename="/home/youssefokab/catkin_ws/src/Matlab_urdf/meshes/rear_right_upper_leg_collision.stl"/>
      </geometry>
    </collision>
    <inertial>
      <mass value="1.5"/>
      <inertia ixx="0.0" ixy="0.0" ixz="0.0" iyy="0.05" iyz="0.0" izz="0.0"/>
    </inertial>
  </link>
  <joint name="rear_right_hip_y" type="revolute">
    <origin rpy="0 0 0" xyz="0.0 -0.110945 0.0"/>
    <axis xyz="0 1 0"/>
    <parent link="rear_right_hip"/>
    <child link="rear_right_upper_leg"/>
    <dynamics damping="0.1" friction="0.1"/>
    <limit effort="1000" lower="-0.89884456477707963539" upper="2.2951079663725435509" velocity="1000.00"/>
  </joint>
  <transmission name="rear_right_hip_y_trans">
    <type>transmission_interface/SimpleTransmission</type>
    <joint name="rear_right_hip_y">
      <hardwareInterface>EffortJointInterface</hardwareInterface>
    </joint>
    <actuator name="rear_right_hip_y">
      <mechanicalReduction>50</mechanicalReduction>
      <hardwareInterface>EffortJointInterface</hardwareInterface>
    </actuator>
  </transmission>
  <!-- rear_right_lower_leg -->
  <link name="rear_right_lower_leg">
    <visual>
      <geometry>
        <mesh filename="/home/youssefokab/catkin_ws/src/Matlab_urdf/meshes/rear_right_lower_leg.stl"/>
      </geometry>
    </visual>
    <collision name="rear_right_lower_leg_fixed_joint_lump__rear_bump_sensor">
      <geometry>
        <mesh filename="/home/youssefokab/catkin_ws/src/Matlab_urdf/meshes/rear_right_lower_leg_collision.stl"/>
      </geometry>
    </collision>
    <inertial>
      <mass value="1.0"/>
      <inertia ixx="0.0" ixy="0.0" ixz="0.0" iyy="0.045" iyz="0.0" izz="0.0"/>
    </inertial>
  </link>
  <joint name="rear_right_knee" type="revolute">
    <origin rpy="0 0 0" xyz="0.025 0.000 -0.3205"/>
    <axis xyz="0 1 0"/>
    <parent link="rear_right_upper_leg"/>
    <child link="rear_right_lower_leg"/>
    <dynamics damping="0.1" friction="0.1"/>
    <limit effort="1000" lower="-2.7929" upper="-0.257725" velocity="1000.00"/>
  </joint>
  <!-- Contact Sensor -->
  <gazebo reference="rear_right_lower_leg">
    <sensor name="rear_right_lower_leg_contactsensor_sensor" type="contact">
      <always_on>true</always_on>
      <contact>
        <collision>rear_right_lower_leg_fixed_joint_lump__rear_bump_sensor_collision</collision>
      </contact>
      <plugin filename="libgazebo_ros_bumper.so" name="rear_right_lower_leg_plugin">
        <bumperTopicName>rear_right_lower_leg_contact</bumperTopicName>
        <frameName>rear_right_lower_leg</frameName>
      </plugin>
    </sensor>
  </gazebo>
  <transmission name="rear_right_knee_trans">
    <type>transmission_interface/SimpleTransmission</type>
    <joint name="rear_right_knee">
      <hardwareInterface>EffortJointInterface</hardwareInterface>
    </joint>
    <actuator name="rear_right_knee">
      <mechanicalReduction>50</mechanicalReduction>
      <hardwareInterface>EffortJointInterface</hardwareInterface>
    </actuator>
  </transmission>
  <gazebo>
    <plugin filename="libgazebo_ros_control.so" name="gazebo_ros_control">
      <!--    	<robotNamespace>/spot1</robotNamespace>-->
    </plugin>
  </gazebo>
</robot>
